"""Testes unit√°rios para o m√≥dulo core de exce√ß√µes."""

import pytest
from unittest.mock import patch, MagicMock

from app.core.exceptions import (
    AppException,
    DataFetchError,
    DataProcessingError,
    AuthenticationError,
    ValidationError,
    ErrorHandler,
    safe_operation,
    validate_data,
    validate_not_empty
)


class TestAppException:
    """Testes para a exce√ß√£o base AppException."""
    
    def test_app_exception_creation(self):
        """Testa cria√ß√£o de AppException."""
        context = {"key": "value"}
        exception = AppException("Test message", context)
        
        assert exception.message == "Test message"
        assert exception.context == context
        assert exception.timestamp is not None
        assert str(exception) == "Test message"
    
    def test_app_exception_without_context(self):
        """Testa cria√ß√£o de AppException sem contexto."""
        exception = AppException("Test message")
        
        assert exception.message == "Test message"
        assert exception.context == {}


class TestSpecificExceptions:
    """Testes para exce√ß√µes espec√≠ficas."""
    
    def test_data_fetch_error(self):
        """Testa DataFetchError."""
        error = DataFetchError("Fetch failed")
        assert isinstance(error, AppException)
        assert error.message == "Fetch failed"
    
    def test_data_processing_error(self):
        """Testa DataProcessingError."""
        error = DataProcessingError("Processing failed")
        assert isinstance(error, AppException)
        assert error.message == "Processing failed"
    
    def test_authentication_error(self):
        """Testa AuthenticationError."""
        error = AuthenticationError("Auth failed")
        assert isinstance(error, AppException)
        assert error.message == "Auth failed"
    
    def test_validation_error(self):
        """Testa ValidationError."""
        error = ValidationError("Validation failed")
        assert isinstance(error, AppException)
        assert error.message == "Validation failed"


class TestErrorHandler:
    """Testes para a classe ErrorHandler."""
    
    @patch('streamlit.error')
    @patch('app.core.logging.app_logger')
    def test_handle_data_fetch_error(self, mock_logger, mock_st_error):
        """Testa manipula√ß√£o de DataFetchError."""
        error = DataFetchError("API failed")
        ErrorHandler.handle_error(error)
        
        mock_logger.log_error.assert_called_once_with(error, None)
        mock_st_error.assert_called_once_with("‚ùå Erro ao carregar dados. Verifique sua conex√£o.")
    
    @patch('streamlit.error')
    @patch('app.core.logging.app_logger')
    def test_handle_authentication_error(self, mock_logger, mock_st_error):
        """Testa manipula√ß√£o de AuthenticationError."""
        error = AuthenticationError("Login failed")
        ErrorHandler.handle_error(error)
        
        mock_logger.log_error.assert_called_once_with(error, None)
        mock_st_error.assert_called_once_with("üîê Erro de autentica√ß√£o. Verifique suas credenciais.")
    
    @patch('streamlit.error')
    @patch('app.core.logging.app_logger')
    def test_handle_custom_message(self, mock_logger, mock_st_error):
        """Testa manipula√ß√£o com mensagem customizada."""
        error = Exception("Generic error")
        custom_message = "Custom error message"
        
        ErrorHandler.handle_error(error, user_message=custom_message)
        
        mock_logger.log_error.assert_called_once_with(error, None)
        mock_st_error.assert_called_once_with(custom_message)
    
    def test_safe_execute_success(self):
        """Testa execu√ß√£o segura com sucesso."""
        def test_func(x, y):
            return x + y
        
        result = ErrorHandler.safe_execute(test_func, 1, 2)
        assert result == 3
    
    @patch('app.core.exceptions.ErrorHandler.handle_error')
    def test_safe_execute_error(self, mock_handle_error):
        """Testa execu√ß√£o segura com erro."""
        def failing_func():
            raise ValueError("Test error")
        
        fallback = "fallback_value"
        result = ErrorHandler.safe_execute(failing_func, fallback_value=fallback)
        
        assert result == fallback
        mock_handle_error.assert_called_once()


class TestSafeOperation:
    """Testes para o decorator safe_operation."""
    
    def test_safe_operation_success(self):
        """Testa decorator com fun√ß√£o que executa com sucesso."""
        
        @safe_operation(fallback_value="fallback")
        def test_function(x):
            return x * 2
        
        result = test_function(5)
        assert result == 10
    
    @patch('app.core.exceptions.ErrorHandler.handle_error')
    def test_safe_operation_error(self, mock_handle_error):
        """Testa decorator com fun√ß√£o que falha."""
        
        @safe_operation(fallback_value="fallback")
        def failing_function():
            raise ValueError("Test error")
        
        result = failing_function()
        assert result == "fallback"
        mock_handle_error.assert_called_once()


class TestValidationFunctions:
    """Testes para fun√ß√µes de valida√ß√£o."""
    
    def test_validate_data_success(self):
        """Testa valida√ß√£o de dados com sucesso."""
        # N√£o deve gerar exce√ß√£o
        validate_data("test", str, "test_field")
        validate_data(123, int, "number_field")
        validate_data([], list, "list_field")
    
    def test_validate_data_failure(self):
        """Testa valida√ß√£o de dados com falha."""
        with pytest.raises(ValidationError) as exc_info:
            validate_data("test", int, "number_field")
        
        assert "number_field deve ser do tipo int" in str(exc_info.value)
    
    def test_validate_not_empty_success(self):
        """Testa valida√ß√£o de n√£o vazio com sucesso."""
        # N√£o deve gerar exce√ß√£o
        validate_not_empty("test", "string_field")
        validate_not_empty([1, 2, 3], "list_field")
        validate_not_empty({"key": "value"}, "dict_field")
    
    def test_validate_not_empty_failure(self):
        """Testa valida√ß√£o de n√£o vazio com falha."""
        test_cases = [
            ("", "empty_string"),
            ([], "empty_list"),
            ({}, "empty_dict"),
            (None, "none_value"),
            (0, "zero_value")
        ]
        
        for empty_value, field_name in test_cases:
            with pytest.raises(ValidationError) as exc_info:
                validate_not_empty(empty_value, field_name)
            
            assert f"{field_name} n√£o pode estar vazio" in str(exc_info.value)


if __name__ == "__main__":
    pytest.main([__file__])
